Workbook

Sheet Исходные данные
A1: № пп | B1: y | C1: x1 | D1: x2 | E1: x3 | F1: x4 | G1: y12 | H1: y14 | I1: y23 | J1: y24 | K1: y34
A2: 1 | B2: 0.904 | C2: 75.5 | D2: 25.2 | E2: 3343 | F2: 77 | G2: ='Уравнения регрессии 1 ряд'!J5 -> -0.50184039 | H2: ='Уравнения регрессии 1 ряд'!J41 -> 0.19065838 | I2: ='Уравнения регрессии 1 ряд'!J59 -> 1.5763812 | J2: ='Уравнения регрессии 1 ряд'!J77 -> 0.95524398 | K2: ='Уравнения регрессии 1 ряд'!J95 -> 0.90746343
A3: 2 | B3: 0.922 | C3: 78.5 | D3: 21.8 | E3: 3001 | F3: 78.2 | G3: ='Уравнения регрессии 1 ряд'!J6 -> -0.49662111 | H3: ='Уравнения регрессии 1 ряд'!J42 -> 0.20012849 | I3: ='Уравнения регрессии 1 ряд'!J60 -> 1.5217824 | J3: ='Уравнения регрессии 1 ряд'!J78 -> 0.97585181 | K3: ='Уравнения регрессии 1 ряд'!J96 -> 0.93243739
A4: 3 | B4: 0.763 | C4: 78.4 | D4: 25.7 | E4: 3101 | F4: 68 | G4: ='Уравнения регрессии 1 ряд'!J7 -> -0.53132691 | H4: ='Уравнения регрессии 1 ряд'!J43 -> 0.0020668794 | I4: ='Уравнения регрессии 1 ряд'!J61 -> 1.5836156 | J4: ='Уравнения регрессии 1 ряд'!J79 -> 0.77191977 | K4: ='Уравнения регрессии 1 ряд'!J97 -> 0.71886291
A5: 4 | B5: 0.923 | C5: 77.7 | D5: 17.8 | E5: 3543 | F5: 77.2 | G5: ='Уравнения регрессии 1 ряд'!J8 -> -0.45326745 | H5: ='Уравнения регрессии 1 ряд'!J44 -> 0.18436816 | I5: ='Уравнения регрессии 1 ряд'!J62 -> 1.4601168 | J5: ='Уравнения регрессии 1 ряд'!J80 -> 0.95081605 | K5: ='Уравнения регрессии 1 ряд'!J98 -> 0.9117444
A6: 5 | B6: 0.918 | C6: 84.4 | D6: 15.9 | E6: 3237 | F6: 77.2 | G6: ='Уравнения регрессии 1 ряд'!J9 -> -0.49353039 | H6: ='Уравнения регрессии 1 ряд'!J45 -> 0.15335674 | I6: ='Уравнения регрессии 1 ряд'!J63 -> 1.4292932 | J6: ='Уравнения регрессии 1 ряд'!J81 -> 0.94862988 | K6: ='Уравнения регрессии 1 ряд'!J99 -> 0.91160314
A7: 6 | B7: 0.906 | C7: 75.9 | D7: 22.4 | E7: 3330 | F7: 77.2 | G7: ='Уравнения регрессии 1 ряд'!J10 -> -0.47974448 | H7: ='Уравнения регрессии 1 ряд'!J46 -> 0.19269959 | I7: ='Уравнения регрессии 1 ряд'!J64 -> 1.5321481 | J7: ='Уравнения регрессии 1 ряд'!J82 -> 0.9561089 | K7: ='Уравнения регрессии 1 ряд'!J100 -> 0.91164607
A8: 7 | B8: 0.905 | C8: 76 | D8: 20.6 | E8: 3808 | F8: 75.7 | G8: ='Уравнения регрессии 1 ряд'!J11 -> -0.46418924 | H8: ='Уравнения регрессии 1 ряд'!J47 -> 0.16304195 | I8: ='Уравнения регрессии 1 ряд'!J65 -> 1.5050352 | J8: ='Уравнения регрессии 1 ряд'!J83 -> 0.92338787 | K8: ='Уравнения регрессии 1 ряд'!J101 -> 0.88045194
A9: 8 | B9: 0.545 | C9: 67.5 | D9: 25.2 | E9: 2415 | F9: 62.6 | G9: ='Уравнения регрессии 1 ряд'!J12 -> -0.43307662 | H9: ='Уравнения регрессии 1 ряд'!J48 -> -0.052582892 | I9: ='Уравнения регрессии 1 ряд'!J66 -> 1.5738575 | J9: ='Уравнения регрессии 1 ряд'!J84 -> 0.66100475 | K9: ='Уравнения регрессии 1 ряд'!J102 -> 0.60545294
A10: 9 | B10: 0.894 | C10: 78.2 | D10: 20.7 | E10: 3295 | F10: 78 | G10: ='Уравнения регрессии 1 ряд'!J13 -> -0.48401121 | H10: ='Уравнения регрессии 1 ряд'!J49 -> 0.19762442 | I10: ='Уравнения регрессии 1 ряд'!J67 -> 1.5052186 | J10: ='Уравнения регрессии 1 ряд'!J85 -> 0.97049947 | K10: ='Уравнения регрессии 1 ряд'!J103 -> 0.92838447
A11: 10 | B11: 0.9 | C11: 78.1 | D11: 17.5 | E11: 3504 | F11: 78.2 | G11: ='Уравнения регрессии 1 ряд'!J14 -> -0.45396984 | H11: ='Уравнения регрессии 1 ряд'!J50 -> 0.20197991 | I11: ='Уравнения регрессии 1 ряд'!J68 -> 1.4552752 | J11: ='Уравнения регрессии 1 ряд'!J86 -> 0.97090415 | K11: ='Уравнения регрессии 1 ряд'!J104 -> 0.9326696
A12: 11 | B12: 0.932 | C12: 78.6 | D12: 19.7 | E12: 30565 | F12: 79 | G12: ='Уравнения регрессии 1 ряд'!J15 -> -0.47833008 | H12: ='Уравнения регрессии 1 ряд'!J51 -> 0.21523617 | I12: ='Уравнения регрессии 1 ряд'!J69 -> 1.5635964 | J12: ='Уравнения регрессии 1 ряд'!J87 -> 0.98978213 | K12: ='Уравнения регрессии 1 ряд'!J105 -> 0.96191687
A13: 12 | B13: 0.74 | C13: 84 | D13: 18.5 | E13: 3007 | F13: 67.6 | G13: ='Уравнения регрессии 1 ряд'!J16 -> -0.51380244 | H13: ='Уравнения регрессии 1 ряд'!J52 -> -0.031638387 | I13: ='Уравнения регрессии 1 ряд'!J70 -> 1.4697085 | J13: ='Уравнения регрессии 1 ряд'!J88 -> 0.755462 | K13: ='Уравнения регрессии 1 ряд'!J106 -> 0.71044224
A14: 13 | B14: 0.701 | C14: 59.2 | D14: 54.4 | E14: 2844 | F14: 69.8
A15: 14 | B15: 0.744 | C15: 90.2 | D15: 23 | E15: 2861 | F15: 68.4
A16: 15 | B16: 0.921 | C16: 72.8 | D16: 20.2 | E16: 3259 | F16: 77.9
A17: 16 | B17: 0.927 | C17: 67.7 | D17: 25.2 | E17: 3350 | F17: 78.1
A18: 17 | B18: 0.802 | C18: 82.6 | D18: 22.4 | E18: 3344 | F18: 72.5
A19: 18 | B19: 0.747 | C19: 74.4 | D19: 22.7 | E19: 2704 | F19: 66.6
A20: 19 | B20: 0.927 | C20: 83.3 | D20: 18.1 | E20: 3642 | F20: 76.7
A21: 20 | B21: 0.721 | C21: 83.7 | D21: 20.1 | E21: 2753 | F21: 68.8
A22: 21 | B22: 0.913 | C22: 73.8 | D22: 17.3 | E22: 2916 | F22: 76.8
A23: 22 | B23: 0.918 | C23: 79.2 | D23: 16.8 | E23: 3551 | F23: 78.1
A24: 23 | B24: 0.833 | C24: 71.5 | D24: 29.9 | E24: 3177 | F24: 73.9
A25: 24 | B25: 0.914 | C25: 75.3 | D25: 20.3 | E25: 3280 | F25: 78.6
A26: 25 | B26: 0.923 | C26: 79 | D26: 14.1 | E26: 3160 | F26: 78.5

Sheet Уравнения регрессии 1 ряд
A1: 1
B2: Исходные данные | E2: Вспомогательные расчеты | M2: dk0 | N2: =C17 -> 932.8 | O2: =D17 -> 251 | P2: =B17 -> 10.252 | Q2: =(N2*O3*P4+O2*N4*P3+N3*O4*P2)-(P2*O3*N4+O2*N3*P4+P3*O4*N2) -> 58862.926 | S2: min | T2: =P106 -> 0.00087866196
E3: Расчет параметров | J3: Расчет ошибки(s) | N3: =E17 -> 72711.58 | O3: =G17 -> 19408.47 | P3: =H17 -> 799.5934
B4: y | C4: x1 | D4: x2 | E4: x12 | F4: x22 | G4: x1*x2 | H4: y*x1 | I4: y*x2 | J4: y12=k0+k1*x1+k2*x2 | K4: (y - y12)2 | N4: =G17 -> 19408.47 | O4: =F17 -> 5366.66 | P4: =I17 -> 212.4927
B5: ='Исходные данные'!B2 -> 0.904 | C5: ='Исходные данные'!C2 -> 75.5 | D5: ='Исходные данные'!D2 -> 25.2 | E5: =C5*C5 -> 5700.25 | F5: =D5*D5 -> 635.04 | G5: =C5*D5 -> 1902.6 | H5: =B5*C5 -> 68.252 | I5: =B5*D5 -> 22.7808 | J5: =$M$16+$N$16*C5+$O$16*D5 -> -0.50184039 | K5: =(B5-J5)*(B5-J5) -> 1.9763872 | M5: dk1 | N5: =COUNT(B5:B16) -> 12 | O5: =D17 -> 251 | P5: =B17 -> 10.252 | Q5: =(N5*O6*P7+O5*N7*P6+N6*O7*P5)-(P5*O6*N7+O5*N6*P7+P6*O7*N5) -> -1342.3232
B6: ='Исходные данные'!B3 -> 0.922 | C6: ='Исходные данные'!C3 -> 78.5 | D6: ='Исходные данные'!D3 -> 21.8 | E6: =C6*C6 -> 6162.25 | F6: =D6*D6 -> 475.24 | G6: =C6*D6 -> 1711.3 | H6: =B6*C6 -> 72.377 | I6: =B6*D6 -> 20.0996 | J6: =$M$16+$N$16*C6+$O$16*D6 -> -0.49662111 | K6: =(B6-J6)*(B6-J6) -> 2.0124858 | N6: =C17 -> 932.8 | O6: =G17 -> 19408.47 | P6: =H17 -> 799.5934
B7: ='Исходные данные'!B4 -> 0.763 | C7: ='Исходные данные'!C4 -> 78.4 | D7: ='Исходные данные'!D4 -> 25.7 | E7: =C7*C7 -> 6146.56 | F7: =D7*D7 -> 660.49 | G7: =C7*D7 -> 2014.88 | H7: =B7*C7 -> 59.8192 | I7: =B7*D7 -> 19.6091 | J7: =$M$16+$N$16*C7+$O$16*D7 -> -0.53132691 | K7: =(B7-J7)*(B7-J7) -> 1.6752822 | N7: =D17 -> 251 | O7: =F17 -> 5366.66 | P7: =I17 -> 212.4927
B8: ='Исходные данные'!B5 -> 0.923 | C8: ='Исходные данные'!C5 -> 77.7 | D8: ='Исходные данные'!D5 -> 17.8 | E8: =C8*C8 -> 6037.29 | F8: =D8*D8 -> 316.84 | G8: =C8*D8 -> 1383.06 | H8: =B8*C8 -> 71.7171 | I8: =B8*D8 -> 16.4294 | J8: =$M$16+$N$16*C8+$O$16*D8 -> -0.45326745 | K8: =(B8-J8)*(B8-J8) -> 1.8941121 | M8: dk2 | N8: =COUNT(B5:B16) -> 12 | O8: =C17 -> 932.8 | P8: =B17 -> 10.252 | Q8: =(N8*O9*P10+O8*N10*P9+N9*O10*P8)-(P8*O9*N10+O8*N9*P10+P9*O10*N8) -> -1424.131
B9: ='Исходные данные'!B6 -> 0.918 | C9: ='Исходные данные'!C6 -> 84.4 | D9: ='Исходные данные'!D6 -> 15.9 | E9: =C9*C9 -> 7123.36 | F9: =D9*D9 -> 252.81 | G9: =C9*D9 -> 1341.96 | H9: =B9*C9 -> 77.4792 | I9: =B9*D9 -> 14.5962 | J9: =$M$16+$N$16*C9+$O$16*D9 -> -0.49353039 | K9: =(B9-J9)*(B9-J9) -> 1.992418 | N9: =C17 -> 932.8 | O9: =E17 -> 72711.58 | P9: =H17 -> 799.5934
B10: ='Исходные данные'!B7 -> 0.906 | C10: ='Исходные данные'!C7 -> 75.9 | D10: ='Исходные данные'!D7 -> 22.4 | E10: =C10*C10 -> 5760.81 | F10: =D10*D10 -> 501.76 | G10: =C10*D10 -> 1700.16 | H10: =B10*C10 -> 68.7654 | I10: =B10*D10 -> 20.2944 | J10: =$M$16+$N$16*C10+$O$16*D10 -> -0.47974448 | K10: =(B10-J10)*(B10-J10) -> 1.9202878 | N10: =D17 -> 251 | O10: =G17 -> 19408.47 | P10: =I17 -> 212.4927
B11: ='Исходные данные'!B8 -> 0.905 | C11: ='Исходные данные'!C8 -> 76 | D11: ='Исходные данные'!D8 -> 20.6 | E11: =C11*C11 -> 5776 | F11: =D11*D11 -> 424.36 | G11: =C11*D11 -> 1565.6 | H11: =B11*C11 -> 68.78 | I11: =B11*D11 -> 18.643 | J11: =$M$16+$N$16*C11+$O$16*D11 -> -0.46418924 | K11: =(B11-J11)*(B11-J11) -> 1.8746792 | M11: d | N11: =COUNT(B5:B16) -> 12 | O11: =C17 -> 932.8 | P11: =D17 -> 251 | Q11: =(N11*O12*P13+O11*N13*P12+N12*O13*P11)-(P11*O12*N13+O11*N12*P13+P12*O13*N11) -> 156166.34
B12: ='Исходные данные'!B9 -> 0.545 | C12: ='Исходные данные'!C9 -> 67.5 | D12: ='Исходные данные'!D9 -> 25.2 | E12: =C12*C12 -> 4556.25 | F12: =D12*D12 -> 635.04 | G12: =C12*D12 -> 1701 | H12: =B12*C12 -> 36.7875 | I12: =B12*D12 -> 13.734 | J12: =$M$16+$N$16*C12+$O$16*D12 -> -0.43307662 | K12: =(B12-J12)*(B12-J12) -> 0.95663387 | N12: =C17 -> 932.8 | O12: =E17 -> 72711.58 | P12: =G17 -> 19408.47
B13: ='Исходные данные'!B10 -> 0.894 | C13: ='Исходные данные'!C10 -> 78.2 | D13: ='Исходные данные'!D10 -> 20.7 | E13: =C13*C13 -> 6115.24 | F13: =D13*D13 -> 428.49 | G13: =C13*D13 -> 1618.74 | H13: =B13*C13 -> 69.9108 | I13: =B13*D13 -> 18.5058 | J13: =$M$16+$N$16*C13+$O$16*D13 -> -0.48401121 | K13: =(B13-J13)*(B13-J13) -> 1.8989149 | N13: =D17 -> 251 | O13: =G17 -> 19408.47 | P13: =F17 -> 5366.66
B14: ='Исходные данные'!B11 -> 0.9 | C14: ='Исходные данные'!C11 -> 78.1 | D14: ='Исходные данные'!D11 -> 17.5 | E14: =C14*C14 -> 6099.61 | F14: =D14*D14 -> 306.25 | G14: =C14*D14 -> 1366.75 | H14: =B14*C14 -> 70.29 | I14: =B14*D14 -> 15.75 | J14: =$M$16+$N$16*C14+$O$16*D14 -> -0.45396984 | K14: =(B14-J14)*(B14-J14) -> 1.8332343
B15: ='Исходные данные'!B12 -> 0.932 | C15: ='Исходные данные'!C12 -> 78.6 | D15: ='Исходные данные'!D12 -> 19.7 | E15: =C15*C15 -> 6177.96 | F15: =D15*D15 -> 388.09 | G15: =C15*D15 -> 1548.42 | H15: =B15*C15 -> 73.2552 | I15: =B15*D15 -> 18.3604 | J15: =$M$16+$N$16*C15+$O$16*D15 -> -0.47833008 | K15: =(B15-J15)*(B15-J15) -> 1.9890309 | M15: k0 | N15: k1 | O15: k2 | P15: o12
B16: ='Исходные данные'!B13 -> 0.74 | C16: ='Исходные данные'!C13 -> 84 | D16: ='Исходные данные'!D13 -> 18.5 | E16: =C16*C16 -> 7056 | F16: =D16*D16 -> 342.25 | G16: =C16*D16 -> 1554 | H16: =B16*C16 -> 62.16 | I16: =B16*D16 -> 13.69 | J16: =$M$16+$N$16*C16+$O$16*D16 -> -0.51380244 | K16: =(B16-J16)*(B16-J16) -> 1.5720206 | M16: =Q2/Q11 -> 0.37692454 | N16: =Q5/Q11 -> -0.0085954707 | O16: =Q8/Q11 -> -0.0091193208 | P16: =K17/COUNT(B5:B16) -> 1.7996239
A17: S | B17: =SUM(B5:B16) -> 10.252 | C17: =SUM(C5:C16) -> 932.8 | D17: =SUM(D5:D16) -> 251 | E17: =SUM(E5:E16) -> 72711.58 | F17: =SUM(F5:F16) -> 5366.66 | G17: =SUM(G5:G16) -> 19408.47 | H17: =SUM(H5:H16) -> 799.5934 | I17: =SUM(I5:I16) -> 212.4927 | ... K17: =SUM(K5:K16) -> 21.595487
A19: 2
B20: Исходные данные | E20: Вспомогательные расчеты | M20: dk0 | N20: =C35 -> 932.8 | O20: =D35 -> 66149 | P20: =B35 -> 10.252 | Q20: =(N20*O21*P22+O20*N22*P21+N21*O22*P20)-(P20*O21*N22+O20*N21*P22+P21*O22*N20) -> -2.5865203e+11
E21: Расчет параметров | J21: Расчет ошибки(s) | N21: =E35 -> 72711.58 | O21: =G35 -> 5171083.2 | P21: =H35 -> 799.5934
B22: y | C22: x1 | D22: x3 | E22: x12 | F22: x32 | G22: x1*x3 | H22: y*x1 | I22: y*x3 | J22: y13=k0+k1*x1+k2*x3 | K22: (y - y13)2 | N22: =G35 -> 5171083.2 | O22: =F35 -> 1050647173 | P22: =I35 -> 58987.297
B23: ='Исходные данные'!B2 -> 0.904 | C23: ='Исходные данные'!C2 -> 75.5 | D23: ='Исходные данные'!E2 -> 3343 | E23: =C23*C23 -> 5700.25 | F23: =D23*D23 -> 11175649 | G23: =C23*D23 -> 252396.5 | H23: =B23*C23 -> 68.252 | I23: =B23*D23 -> 3022.072 | J23: =$M$34+$N$34*C23+$O$34*D23 -> -1.1117591 | K23: =(B23-J23)*(B23-J23) -> 4.0632849 | M23: dk1 | N23: =COUNT(B23:B34) -> 12 | O23: =D35 -> 66149 | P23: =B35 -> 10.252 | Q23: =(N23*O24*P25+O23*N25*P24+N24*O25*P23)-(P23*O24*N25+O23*N24*P25+P24*O25*N23) -> -2.1126121e+10
B24: ='Исходные данные'!B3 -> 0.922 | C24: ='Исходные данные'!C3 -> 78.5 | D24: ='Исходные данные'!E3 -> 3001 | E24: =C24*C24 -> 6162.25 | F24: =D24*D24 -> 9006001 | G24: =C24*D24 -> 235578.5 | H24: =B24*C24 -> 72.377 | I24: =B24*D24 -> 2766.922 | J24: =$M$34+$N$34*C24+$O$34*D24 -> -1.151169 | K24: =(B24-J24)*(B24-J24) -> 4.2980296 | N24: =C35 -> 932.8 | O24: =G35 -> 5171083.2 | P24: =H35 -> 799.5934
B25: ='Исходные данные'!B4 -> 0.763 | C25: ='Исходные данные'!C4 -> 78.4 | D25: ='Исходные данные'!E4 -> 3101 | E25: =C25*C25 -> 6146.56 | F25: =D25*D25 -> 9616201 | G25: =C25*D25 -> 243118.4 | H25: =B25*C25 -> 59.8192 | I25: =B25*D25 -> 2366.063 | J25: =$M$34+$N$34*C25+$O$34*D25 -> -1.1495839 | K25: =(B25-J25)*(B25-J25) -> 3.657977 | N25: =D35 -> 66149 | O25: =F35 -> 1050647173 | P25: =I35 -> 58987.297
B26: ='Исходные данные'!B5 -> 0.923 | C26: ='Исходные данные'!C5 -> 77.7 | D26: ='Исходные данные'!E5 -> 3543 | E26: =C26*C26 -> 6037.29 | F26: =D26*D26 -> 12552849 | G26: =C26*D26 -> 275291.1 | H26: =B26*C26 -> 71.7171 | I26: =B26*D26 -> 3270.189 | J26: =$M$34+$N$34*C26+$O$34*D26 -> -1.1392785 | K26: =(B26-J26)*(B26-J26) -> 4.2529925 | M26: dk2 | N26: =COUNT(B23:B34) -> 12 | O26: =C35 -> 932.8 | P26: =B35 -> 10.252 | Q26: =(N26*O27*P28+O26*N28*P27+N27*O28*P26)-(P26*O27*N28+O26*N27*P28+P27*O28*N26) -> 5061965.9
B27: ='Исходные данные'!B6 -> 0.918 | C27: ='Исходные данные'!C6 -> 84.4 | D27: ='Исходные данные'!E6 -> 3237 | E27: =C27*C27 -> 7123.36 | F27: =D27*D27 -> 10478169 | G27: =C27*D27 -> 273202.8 | H27: =B27*C27 -> 77.4792 | I27: =B27*D27 -> 2971.566 | J27: =$M$34+$N$34*C27+$O$34*D27 -> -1.2258912 | K27: =(B27-J27)*(B27-J27) -> 4.5962693 | N27: =C35 -> 932.8 | O27: =E35 -> 72711.58 | P27: =H35 -> 799.5934
B28: ='Исходные данные'!B7 -> 0.906 | C28: ='Исходные данные'!C7 -> 75.9 | D28: ='Исходные данные'!E7 -> 3330 | E28: =C28*C28 -> 5760.81 | F28: =D28*D28 -> 11088900 | G28: =C28*D28 -> 252747 | H28: =B28*C28 -> 68.7654 | I28: =B28*D28 -> 3016.98 | J28: =$M$34+$N$34*C28+$O$34*D28 -> -1.1169139 | K28: =(B28-J28)*(B28-J28) -> 4.0921806 | N28: =D35 -> 66149 | O28: =G35 -> 5171083.2 | P28: =I35 -> 58987.297
B29: ='Исходные данные'!B8 -> 0.905 | C29: ='Исходные данные'!C8 -> 76 | D29: ='Исходные данные'!E8 -> 3808 | E29: =C29*C29 -> 5776 | F29: =D29*D29 -> 14500864 | G29: =C29*D29 -> 289408 | H29: =B29*C29 -> 68.78 | I29: =B29*D29 -> 3446.24 | J29: =$M$34+$N$34*C29+$O$34*D29 -> -1.1167281 | K29: =(B29-J29)*(B29-J29) -> 4.0873844 | M29: d | N29: =COUNT(B23:B34) -> 12 | O29: =C35 -> 932.8 | P29: =D35 -> 66149 | Q29: =(N29*O30*P31+O29*N31*P30+N30*O31*P29)-(P29*O30*N31+O29*N30*P31+P30*O31*N29) -> 1.6521133e+12
B30: ='Исходные данные'!B9 -> 0.545 | C30: ='Исходные данные'!C9 -> 67.5 | D30: ='Исходные данные'!E9 -> 2415 | E30: =C30*C30 -> 4556.25 | F30: =D30*D30 -> 5832225 | G30: =C30*D30 -> 163012.5 | H30: =B30*C30 -> 36.7875 | I30: =B30*D30 -> 1316.175 | J30: =$M$34+$N$34*C30+$O$34*D30 -> -1.0123038 | K30: =(B30-J30)*(B30-J30) -> 2.4251951 | N30: =C35 -> 932.8 | O30: =E35 -> 72711.58 | P30: =G35 -> 5171083.2
B31: ='Исходные данные'!B10 -> 0.894 | C31: ='Исходные данные'!C10 -> 78.2 | D31: ='Исходные данные'!E10 -> 3295 | E31: =C31*C31 -> 6115.24 | F31: =D31*D31 -> 10857025 | G31: =C31*D31 -> 257669 | H31: =B31*C31 -> 69.9108 | I31: =B31*D31 -> 2945.73 | J31: =$M$34+$N$34*C31+$O$34*D31 -> -1.146432 | K31: =(B31-J31)*(B31-J31) -> 4.1633627 | N31: =D35 -> 66149 | O31: =G35 -> 5171083.2 | P31: =F35 -> 1050647173
B32: ='Исходные данные'!B11 -> 0.9 | C32: ='Исходные данные'!C11 -> 78.1 | D32: ='Исходные данные'!E11 -> 3504 | E32: =C32*C32 -> 6099.61 | F32: =D32*D32 -> 12278016 | G32: =C32*D32 -> 273662.4 | H32: =B32*C32 -> 70.29 | I32: =B32*D32 -> 3153.6 | J32: =$M$34+$N$34*C32+$O$34*D32 -> -1.1445129 | K32: =(B32-J32)*(B32-J32) -> 4.180033
B33: ='Исходные данные'!B12 -> 0.932 | C33: ='Исходные данные'!C12 -> 78.6 | D33: ='Исходные данные'!E12 -> 30565 | E33: =C33*C33 -> 6177.96 | F33: =D33*D33 -> 934219225 | G33: =C33*D33 -> 2402409 | H33: =B33*C33 -> 73.2552 | I33: =B33*D33 -> 28486.58 | J33: =$M$34+$N$34*C33+$O$34*D33 -> -1.0679934 | K33: =(B33-J33)*(B33-J33) -> 3.9999738 | M33: k0 | N33: k1 | O33: k2 | P33: o12
B34: ='Исходные данные'!B13 -> 0.74 | C34: ='Исходные данные'!C13 -> 84 | D34: ='Исходные данные'!E13 -> 3007 | E34: =C34*C34 -> 7056 | F34: =D34*D34 -> 9042049 | G34: =C34*D34 -> 252588 | H34: =B34*C34 -> 62.16 | I34: =B34*D34 -> 2225.18 | J34: =$M$34+$N$34*C34+$O$34*D34 -> -1.2214809 | K34: =(B34-J34)*(B34-J34) -> 3.8474074 | M34: =Q20/Q29 -> -0.15655829 | N34: =Q23/Q29 -> -0.012787332 | O34: =Q26/Q29 -> 3.0639339e-06 | P34: =K35/COUNT(B23:B34) -> 3.9720075
A35: S | B35: =SUM(B23:B34) -> 10.252 | C35: =SUM(C23:C34) -> 932.8 | D35: =SUM(D23:D34) -> 66149 | E35: =SUM(E23:E34) -> 72711.58 | F35: =SUM(F23:F34) -> 1050647173 | G35: =SUM(G23:G34) -> 5171083.2 | H35: =SUM(H23:H34) -> 799.5934 | I35: =SUM(I23:I34) -> 58987.297 | ... K35: =SUM(K23:K34) -> 47.66409
A37: 3
B38: Исходные данные | E38: Вспомогательные расчеты | M38: dk0 | N38: =C53 -> 932.8 | O38: =D53 -> 895.9 | P38: =B53 -> 10.252 | Q38: =(N38*O39*P40+O38*N40*P39+N39*O40*P38)-(P38*O39*N40+O38*N39*P40+P39*O40*N38) -> -653096.01
E39: Расчет параметров | J39: Расчет ошибки(s) | N39: =E53 -> 72711.58 | O39: =G53 -> 69730.52 | P39: =H53 -> 799.5934
B40: y | C40: x1 | D40: x4 | E40: x12 | F40: x42 | G40: x1*x4 | H40: y*x1 | I40: y*x4 | J40: y14=k0+k1*x1+k2*x4 | K40: (y - y14)2 | N40: =G53 -> 69730.52 | O40: =F53 -> 67207.01 | P40: =I53 -> 772.0503
B41: ='Исходные данные'!B2 -> 0.904 | C41: ='Исходные данные'!C2 -> 75.5 | D41: ='Исходные данные'!F2 -> 77 | E41: =C41*C41 -> 5700.25 | F41: =D41*D41 -> 5929 | G41: =C41*D41 -> 5813.5 | H41: =B41*C41 -> 68.252 | I41: =B41*D41 -> 69.608 | J41: =$M$52+$N$52*C41+$O$52*D41 -> 0.19065838 | K41: =(B41-J41)*(B41-J41) -> 0.50885627 | M41: dk1 | N41: =COUNT(B41:B52) -> 12 | O41: =D53 -> 895.9 | P41: =B53 -> 10.252 | Q41: =(N41*O42*P43+O41*N43*P42+N42*O43*P41)-(P41*O42*N43+O41*N42*P43+P42*O43*N41) -> -3153.6194
B42: ='Исходные данные'!B3 -> 0.922 | C42: ='Исходные данные'!C3 -> 78.5 | D42: ='Исходные данные'!F3 -> 78.2 | E42: =C42*C42 -> 6162.25 | F42: =D42*D42 -> 6115.24 | G42: =C42*D42 -> 6138.7 | H42: =B42*C42 -> 72.377 | I42: =B42*D42 -> 72.1004 | J42: =$M$52+$N$52*C42+$O$52*D42 -> 0.20012849 | K42: =(B42-J42)*(B42-J42) -> 0.52109848 | N42: =C53 -> 932.8 | O42: =G53 -> 69730.52 | P42: =H53 -> 799.5934
...

Sheet Уравнения регрессии 2 ряд
A1: 1
B2: Исходные данные | E2: Вспомогательные расчеты | M2: dk0 | N2: =C17 -> -5.7837101 | O2: =D17 -> 1.6169394 | P2: =B17 -> 10.252 | Q2: =(N2*O3*P4+O2*N4*P3+N3*O4*P2)-(P2*O3*N4+O2*N3*P4+P3*O4*N2) -> 0.001364631 | S2: min | T2: =P124 -> 0.094401323
E3: Расчет параметров | J3: Расчет ошибки(s) | N3: =E17 -> 2.7961381 | O3: =G17 -> -0.77482033 | P3: =H17 -> -4.9464404
B4: y | C4: y12 | D4: y14 | E4: x12 | F4: x22 | G4: x1*x2 | H4: y*x1 | I4: y*x2 | J4: y12=k0+k1*x1+k2*x2 | K4: (y - y12)2 | N4: =G17 -> -0.77482033 | O4: =F17 -> 0.32757587 | P4: =I17 -> 1.4985309
B5: ='Исходные данные'!B2 -> 0.904 | C5: ='Исходные данные'!G2 -> -0.50184039 | D5: ='Исходные данные'!H2 -> 0.19065838 | E5: =C5*C5 -> 0.25184377 | F5: =D5*D5 -> 0.036350617 | G5: =C5*D5 -> -0.095680073 | H5: =B5*C5 -> -0.45366371 | I5: =B5*D5 -> 0.17235517 | J5: =$M$16+$N$16*C5+$O$16*D5 -> -0.26626546 | K5: =(B5-J5)*(B5-J5) -> 1.3695213 | M5: dk1 | N5: =COUNT(B5:B16) -> 12 | O5: =D17 -> 1.6169394 | P5: =B17 -> 10.252 | Q5: =(N5*O6*P7+O5*N7*P6+N6*O7*P5)-(P5*O6*N7+O5*N6*P7+P6*O7*N5) -> 0.01320938
B6: ='Исходные данные'!B3 -> 0.922 | C6: ='Исходные данные'!G3 -> -0.49662111 | D6: ='Исходные данные'!H3 -> 0.20012849 | E6: =C6*C6 -> 0.24663252 | F6: =D6*D6 -> 0.040051411 | G6: =C6*D6 -> -0.09938803 | H6: =B6*C6 -> -0.45788466 | I6: =B6*D6 -> 0.18451846 | J6: =$M$16+$N$16*C6+$O$16*D6 -> -0.24941046 | K6: =(B6-J6)*(B6-J6) -> 1.3722025 | N6: =C17 -> -5.7837101 | O6: =G17 -> -0.77482033 | P6: =H17 -> -4.9464404
B7: ='Исходные данные'!B4 -> 0.763 | C7: ='Исходные данные'!G4 -> -0.53132691 | D7: ='Исходные данные'!H4 -> 0.0020668794 | E7: =C7*C7 -> 0.28230829 | F7: =D7*D7 -> 4.2719903e-06 | G7: =C7*D7 -> -0.0010981886 | H7: =B7*C7 -> -0.40540243 | I7: =B7*D7 -> 0.0015770289 | J7: =$M$16+$N$16*C7+$O$16*D7 -> -0.51239235 | K7: =(B7-J7)*(B7-J7) -> 1.6266256 | N7: =D17 -> 1.6169394 | O7: =F17 -> 0.32757587 | P7: =I17 -> 1.4985309
B8: ='Исходные данные'!B5 -> 0.923 | C8: ='Исходные данные'!G5 -> -0.45326745 | D8: ='Исходные данные'!H5 -> 0.18436816 | E8: =C8*C8 -> 0.20545138 | F8: =D8*D8 -> 0.033991618 | G8: =C8*D8 -> -0.083568085 | H8: =B8*C8 -> -0.41836585 | I8: =B8*D8 -> 0.17017181 | J8: =$M$16+$N$16*C8+$O$16*D8 -> -0.21488216 | K8: =(B8-J8)*(B8-J8) -> 1.2947758 | M8: dk2 | N8: =COUNT(B5:B16) -> 12 | O8: =C17 -> -5.7837101 | P8: =B17 -> 10.252 | Q8: =(N8*O9*P10+O8*N10*P9+N9*O10*P8)-(P8*O9*N10+O8*N9*P10+P9*O10*N8) -> 0.012270679
B9: ='Исходные данные'!B6 -> 0.918 | C9: ='Исходные данные'!G6 -> -0.49353039 | D9: ='Исходные данные'!H6 -> 0.15335674 | E9: =C9*C9 -> 0.24357225 | F9: =D9*D9 -> 0.023518289 | G9: =C9*D9 -> -0.075686211 | H9: =B9*C9 -> -0.4530609 | I9: =B9*D9 -> 0.14078149 | J9: =$M$16+$N$16*C9+$O$16*D9 -> -0.29794085 | K9: =(B9-J9)*(B9-J9) -> 1.4785122 | N9: =C17 -> -5.7837101 | O9: =E17 -> 2.7961381 | P9: =H17 -> -4.9464404
B10: ='Исходные данные'!B7 -> 0.906 | C10: ='Исходные данные'!G7 -> -0.47974448 | D10: ='Исходные данные'!H7 -> 0.19269959 | E10: =C10*C10 -> 0.23015476 | F10: =D10*D10 -> 0.03713313 | G10: =C10*D10 -> -0.092446561 | H10: =B10*C10 -> -0.43464849 | I10: =B10*D10 -> 0.17458582 | J10: =$M$16+$N$16*C10+$O$16*D10 -> -0.23741455 | K10: =(B10-J10)*(B10-J10) -> 1.3073968 | N10: =D17 -> 1.6169394 | O10: =G17 -> -0.77482033 | P10: =I17 -> 1.4985309
B11: ='Исходные данные'!B8 -> 0.905 | C11: ='Исходные данные'!G8 -> -0.46418924 | D11: ='Исходные данные'!H8 -> 0.16304195 | E11: =C11*C11 -> 0.21547165 | F11: =D11*D11 -> 0.026582679 | G11: =C11*D11 -> -0.075682322 | H11: =B11*C11 -> -0.42009127 | I11: =B11*D11 -> 0.14755297 | J11: =$M$16+$N$16*C11+$O$16*D11 -> -0.25183856 | K11: =(B11-J11)*(B11-J11) -> 1.3382755 | M11: d | N11: =COUNT(B5:B16) -> 12 | O11: =C17 -> -5.7837101 | P11: =D17 -> 1.6169394 | Q11: =(N11*O12*P13+O11*N13*P12+N12*O13*P11)-(P11*O12*N13+O11*N12*P13+P12*O13*N11) -> 0.010984758
B12: ='Исходные данные'!B9 -> 0.545 | C12: ='Исходные данные'!G9 -> -0.43307662 | D12: ='Исходные данные'!H9 -> -0.052582892 | E12: =C12*C12 -> 0.18755536 | F12: =D12*D12 -> 0.0027649605 | G12: =C12*D12 -> 0.022772421 | H12: =B12*C12 -> -0.23602676 | I12: =B12*D12 -> -0.028657676 | J12: =$M$16+$N$16*C12+$O$16*D12 -> -0.4552918 | K12: =(B12-J12)*(B12-J12) -> 1.0005837 | N12: =C17 -> -5.7837101 | O12: =E17 -> 2.7961381 | P12: =G17 -> -0.77482033
B13: ='Исходные данные'!B10 -> 0.894 | C13: ='Исходные данные'!G10 -> -0.48401121 | D13: ='Исходные данные'!H10 -> 0.19762442 | E13: =C13*C13 -> 0.23426685 | F13: =D13*D13 -> 0.039055411 | G13: =C13*D13 -> -0.095652435 | H13: =B13*C13 -> -0.43270602 | I13: =B13*D13 -> 0.17667623 | J13: =$M$16+$N$16*C13+$O$16*D13 -> -0.23704403 | K13: =(B13-J13)*(B13-J13) -> 1.2792606 | N13: =D17 -> 1.6169394 | O13: =G17 -> -0.77482033 | P13: =F17 -> 0.32757587
B14: ='Исходные данные'!B11 -> 0.9 | C14: ='Исходные данные'!G11 -> -0.45396984 | D14: ='Исходные данные'!H11 -> 0.20197991 | E14: =C14*C14 -> 0.20608861 | F14: =D14*D14 -> 0.040795886 | G14: =C14*D14 -> -0.091692789 | H14: =B14*C14 -> -0.40857285 | I14: =B14*D14 -> 0.18178192 | J14: =$M$16+$N$16*C14+$O$16*D14 -> -0.19605334 | K14: =(B14-J14)*(B14-J14) -> 1.2013329
B15: ='Исходные данные'!B12 -> 0.932 | C15: ='Исходные данные'!G12 -> -0.47833008 | D15: ='Исходные данные'!H12 -> 0.21523617 | E15: =C15*C15 -> 0.22879967 | F15: =D15*D15 -> 0.046326611 | G15: =C15*D15 -> -0.10295394 | H15: =B15*C15 -> -0.44580363 | I15: =B15*D15 -> 0.20060011 | J15: =$M$16+$N$16*C15+$O$16*D15 -> -0.2105389 | K15: =(B15-J15)*(B15-J15) -> 1.3053951 | M15: k0 | N15: k1 | O15: k2 | P15: o12
B16: ='Исходные данные'!B13 -> 0.74 | C16: ='Исходные данные'!G13 -> -0.51380244 | D16: ='Исходные данные'!H13 -> -0.031638387 | E16: =C16*C16 -> 0.26399294 | F16: =D16*D16 -> 0.0010009875 | G16: =C16*D16 -> 0.01625588 | H16: =B16*C16 -> -0.3802138 | I16: =B16*D16 -> -0.023412406 | J16: =$M$16+$N$16*C16+$O$16*D16 -> -0.52896978 | K16: =(B16-J16)*(B16-J16) -> 1.6102843 | M16: =Q2/Q11 -> 0.1242295 | N16: =Q5/Q11 -> 1.202519 | O16: =Q8/Q11 -> 1.117064 | P16: =K17/COUNT(B5:B16) -> 1.3486805
A17: S | B17: =SUM(B5:B16) -> 10.252 | C17: =SUM(C5:C16) -> -5.7837101 | D17: =SUM(D5:D16) -> 1.6169394 | E17: =SUM(E5:E16) -> 2.7961381 | F17: =SUM(F5:F16) -> 0.32757587 | G17: =SUM(G5:G16) -> -0.77482033 | H17: =SUM(H5:H16) -> -4.9464404 | I17: =SUM(I5:I16) -> 1.4985309 | ... K17: =SUM(K5:K16) -> 16.184166
A19: 2
B20: Исходные данные | E20: Вспомогательные расчеты | M20: dk0 | N20: =C35 -> -5.7837101 | O20: =D35 -> 18.176029 | P20: =B35 -> 10.252 | Q20: =(N20*O21*P22+O20*N22*P21+N21*O22*P20)-(P20*O21*N22+O20*N21*P22+P21*O22*N20) -> 0.0052984139
E21: Расчет параметров | J21: Расчет ошибки(s) | N21: =E35 -> 2.7961381 | O21: =G35 -> -8.762992 | P21: =H35 -> -4.9464404
B22: y | C22: y12 | D22: y23 | E22: x12 | F22: x32 | G22: x1*x3 | H22: y*x1 | I22: y*x3 | J22: y13=k0+k1*x1+k2*x3 | K22: (y - y13)2 | N22: =G35 -> -8.762992 | O22: =F35 -> 27.56148 | P22: =I35 -> 15.504414
B23: ='Исходные данные'!B2 -> 0.904 | C23: ='Исходные данные'!G2 -> -0.50184039 | D23: ='Исходные данные'!I2 -> 1.5763812 | E23: =C23*C23 -> 0.25184377 | F23: =D23*D23 -> 2.4849778 | G23: =C23*D23 -> -0.79109177 | H23: =B23*C23 -> -0.45366371 | I23: =B23*D23 -> 1.4250486 | J23: =$M$34+$N$34*C23+$O$34*D23 -> -0.054523147 | K23: =(B23-J23)*(B23-J23) -> 0.91876662 | M23: dk1 | N23: =COUNT(B23:B34) -> 12 | O23: =D35 -> 18.176029 | P23: =B35 -> 10.252 | Q23: =(N23*O24*P25+O23*N25*P24+N24*O25*P23)-(P23*O24*N25+O23*N24*P25+P24*O25*N23) -> 0.0026752104
B24: ='Исходные данные'!B3 -> 0.922 | C24: ='Исходные данные'!G3 -> -0.49662111 | D24: ='Исходные данные'!I3 -> 1.5217824 | E24: =C24*C24 -> 0.24663252 | F24: =D24*D24 -> 2.3158217 | G24: =C24*D24 -> -0.75574927 | H24: =B24*C24 -> -0.45788466 | I24: =B24*D24 -> 1.4030834 | J24: =$M$34+$N$34*C24+$O$34*D24 -> -0.0035120489 | K24: =(B24-J24)*(B24-J24) -> 0.85657255 | N24: =C35 -> -5.7837101 | O24: =G35 -> -8.762992 | P24: =H35 -> -4.9464404
B25: ='Исходные данные'!B4 -> 0.763 | C25: ='Исходные данные'!G4 -> -0.53132691 | D25: ='Исходные данные'!I4 -> 1.5836156 | E25: =C25*C25 -> 0.28230829 | F25: =D25*D25 -> 2.5078382 | G25: =C25*D25 -> -0.84141756 | H25: =B25*C25 -> -0.40540243 | I25: =B25*D25 -> 1.2082987 | J25: =$M$34+$N$34*C25+$O$34*D25 -> -0.086345847 | K25: =(B25-J25)*(B25-J25) -> 0.72138837 | N25: =D35 -> 18.176029 | O25: =F35 -> 27.56148 | P25: =I35 -> 15.504414
B26: ='Исходные данные'!B5 -> 0.923 | C26: ='Исходные данные'!G5 -> -0.45326745 | D26: ='Исходные данные'!I5 -> 1.4601168 | E26: =C26*C26 -> 0.20545138 | F26: =D26*D26 -> 2.131941 | G26: =C26*D26 -> -0.6618234 | H26: =B26*C26 -> -0.41836585 | I26: =B26*D26 -> 1.3476878 | J26: =$M$34+$N$34*C26+$O$34*D26 -> 0.086706491 | K26: =(B26-J26)*(B26-J26) -> 0.69938683 | M26: dk2 | N26: =COUNT(B23:B34) -> 12 | O26: =C35 -> -5.7837101 | P26: =B35 -> 10.252 | Q26: =(N26*O27*P28+O26*N28*P27+N27*O28*P26)-(P26*O27*N28+O26*N27*P28+P27*O28*N26) -> -0.0026157761
B27: ='Исходные данные'!B6 -> 0.918 | C27: ='Исходные данные'!G6 -> -0.49353039 | D27: ='Исходные данные'!I6 -> 1.4292932 | E27: =C27*C27 -> 0.24357225 | F27: =D27*D27 -> 2.0428791 | G27: =C27*D27 -> -0.70539964 | H27: =B27*C27 -> -0.4530609 | I27: =B27*D27 -> 1.3120912 | J27: =$M$34+$N$34*C27+$O$34*D27 -> 0.077894167 | K27: =(B27-J27)*(B27-J27) -> 0.70577781 | N27: =C35 -> -5.7837101 | O27: =E35 -> 2.7961381 | P27: =H35 -> -4.9464404
B28: ='Исходные данные'!B7 -> 0.906 | C28: ='Исходные данные'!G7 -> -0.47974448 | D28: ='Исходные данные'!I7 -> 1.5321481 | E28: =C28*C28 -> 0.23015476 | F28: =D28*D28 -> 2.3474778 | G28: =C28*D28 -> -0.73503959 | H28: =B28*C28 -> -0.43464849 | I28: =B28*D28 -> 1.3881262 | J28: =$M$34+$N$34*C28+$O$34*D28 -> 0.0023556618 | K28: =(B28-J28)*(B28-J28) -> 0.81657309 | N28: =D35 -> 18.176029 | O28: =G35 -> -8.762992 | P28: =I35 -> 15.504414
B29: ='Исходные данные'!B8 -> 0.905 | C29: ='Исходные данные'!G8 -> -0.46418924 | D29: ='Исходные данные'!I8 -> 1.5050352 | E29: =C29*C29 -> 0.21547165 | F29: =D29*D29 -> 2.265131 | G29: =C29*D29 -> -0.69862116 | H29: =B29*C29 -> -0.42009127 | I29: =B29*D29 -> 1.3620569 | J29: =$M$34+$N$34*C29+$O$34*D29 -> 0.038970589 | K29: =(B29-J29)*(B29-J29) -> 0.75000694 | M29: d | N29: =COUNT(B23:B34) -> 12 | O29: =C35 -> -5.7837101 | P29: =D35 -> 18.176029 | Q29: =(N29*O30*P31+O29*N31*P30+N30*O31*P29)-(P29*O30*N31+O29*N30*P31+P30*O31*N29) -> 0.0030734673
B30: ='Исходные данные'!B9 -> 0.545 | C30: ='Исходные данные'!G9 -> -0.43307662 | D30: ='Исходные данные'!I9 -> 1.5738575 | E30: =C30*C30 -> 0.18755536 | F30: =D30*D30 -> 2.4770273 | G30: =C30*D30 -> -0.68160087 | H30: =B30*C30 -> -0.23602676 | I30: =B30*D30 -> 0.85775232 | J30: =$M$34+$N$34*C30+$O$34*D30 -> 0.0074782087 | K30: =(B30-J30)*(B30-J30) -> 0.28892968 | N30: =C35 -> -5.7837101 | O30: =E35 -> 2.7961381 | P30: =G35 -> -8.762992
B31: ='Исходные данные'!B10 -> 0.894 | C31: ='Исходные данные'!G10 -> -0.48401121 | D31: ='Исходные данные'!I10 -> 1.5052186 | E31: =C31*C31 -> 0.23426685 | F31: =D31*D31 -> 2.2656829 | G31: =C31*D31 -> -0.72854266 | H31: =B31*C31 -> -0.43270602 | I31: =B31*D31 -> 1.3456654 | J31: =$M$34+$N$34*C31+$O$34*D31 -> 0.021561085 | K31: =(B31-J31)*(B31-J31) -> 0.76114966 | N31: =D35 -> 18.176029 | O31: =G35 -> -8.762992 | P31: =F35 -> 27.56148
B32: ='Исходные данные'!B11 -> 0.9 | C32: ='Исходные данные'!G11 -> -0.45396984 | D32: ='Исходные данные'!I11 -> 1.4552752 | E32: =C32*C32 -> 0.20608861 | F32: =D32*D32 -> 2.117826 | G32: =C32*D32 -> -0.66065106 | H32: =B32*C32 -> -0.40857285 | I32: =B32*D32 -> 1.3097477 | J32: =$M$34+$N$34*C32+$O$34*D32 -> 0.090215666 | K32: =(B32-J32)*(B32-J32) -> 0.65575067
B33: ='Исходные данные'!B12 -> 0.932 | C33: ='Исходные данные'!G12 -> -0.47833008 | D33: ='Исходные данные'!I12 -> 1.5635964 | E33: =C33*C33 -> 0.22879967 | F33: =D33*D33 -> 2.4448336 | G33: =C33*D33 -> -0.74791517 | H33: =B33*C33 -> -0.44580363 | I33: =B33*D33 -> 1.4572718 | J33: =$M$34+$N$34*C33+$O$34*D33 -> -0.023178286 | K33: =(B33-J33)*(B33-J33) -> 0.91236556 | M33: k0 | N33: k1 | O33: k2 | P33: o12
B34: ='Исходные данные'!B13 -> 0.74 | C34: ='Исходные данные'!G13 -> -0.51380244 | D34: ='Исходные данные'!I13 -> 1.4697085 | E34: =C34*C34 -> 0.26399294 | F34: =D34*D34 -> 2.1600431 | G34: =C34*D34 -> -0.75513981 | H34: =B34*C34 -> -0.3802138 | I34: =B34*D34 -> 1.0875843 | J34: =$M$34+$N$34*C34+$O$34*D34 -> 0.025852187 | K34: =(B34-J34)*(B34-J34) -> 0.5100071 | M34: =Q20/Q29 -> 1.7239207 | N34: =Q23/Q29 -> 0.87042098 | O34: =Q26/Q29 -> -0.85108311 | P34: =K35/COUNT(B23:B34) -> 0.71638957
A35: S | B35: =SUM(B23:B34) -> 10.252 | C35: =SUM(C23:C34) -> -5.7837101 | D35: =SUM(D23:D34) -> 18.176029 | E35: =SUM(E23:E34) -> 2.7961381 | F35: =SUM(F23:F34) -> 27.56148 | G35: =SUM(G23:G34) -> -8.762992 | H35: =SUM(H23:H34) -> -4.9464404 | I35: =SUM(I23:I34) -> 15.504414 | ... K35: =SUM(K23:K34) -> 8.5966749
A37: 3
B38: Исходные данные | E38: Вспомогательные расчеты | M38: dk0 | N38: =C53 -> -5.7837101 | O38: =D53 -> 10.829611 | P38: =B53 -> 10.252 | Q38: =(N38*O39*P40+O38*N40*P39+N39*O40*P38)-(P38*O39*N40+O38*N39*P40+P39*O40*N38) -> -0.0054494913
E39: Расчет параметров | J39: Расчет ошибки(s) | N39: =E53 -> 2.7961381 | O39: =G53 -> -5.218977 | P39: =H53 -> -4.9464404
B40: y | C40: y12 | D40: y24 | E40: x12 | F40: x42 | G40: x1*x4 | H40: y*x1 | I40: y*x4 | J40: y14=k0+k1*x1+k2*x4 | K40: (y - y14)2 | N40: =G53 -> -5.218977 | O40: =F53 -> 9.90322 | P40: =I53 -> 9.3858035
B41: ='Исходные данные'!B2 -> 0.904 | C41: ='Исходные данные'!G2 -> -0.50184039 | D41: ='Исходные данные'!J2 -> 0.95524398 | E41: =C41*C41 -> 0.25184377 | F41: =D41*D41 -> 0.91249106 | G41: =C41*D41 -> -0.47938001 | H41: =B41*C41 -> -0.45366371 | I41: =B41*D41 -> 0.86354056 | J41: =$M$52+$N$52*C41+$O$52*D41 -> 0.23077595 | K41: =(B41-J41)*(B41-J41) -> 0.45323062 | M41: dk1 | N41: =COUNT(B41:B52) -> 12 | O41: =D53 -> 10.829611 | P41: =B53 -> 10.252 | Q41: =(N41*O42*P43+O41*N43*P42+N42*O43*P41)-(P41*O42*N43+O41*N42*P43+P42*O43*N41) -> 0.0091568547
B42: ='Исходные данные'!B3 -> 0.922 | C42: ='Исходные данные'!G3 -> -0.49662111 | D42: ='Исходные данные'!J3 -> 0.97585181 | E42: =C42*C42 -> 0.24663252 | F42: =D42*D42 -> 0.95228676 | G42: =C42*D42 -> -0.48462861 | H42: =B42*C42 -> -0.45788466 | I42: =B42*D42 -> 0.89973537 | J42: =$M$52+$N$52*C42+$O$52*D42 -> 0.25566279 | K42: =(B42-J42)*(B42-J42) -> 0.44400528 | N42: =C53 -> -5.7837101 | O42: =G53 -> -5.218977 | P42: =H53 -> -4.9464404
...

Sheet Итог
B2: Уравнение | C2: Полученные | D2: Исходные
A3: 1 | B3: y= | C3: ='Уравнения регрессии 2 ряд'!$M$124+'Уравнения регрессии 2 ряд'!$N$124*('Уравнения регрессии 1 ряд'!$M$52+'Уравнения регрессии 1 ряд'!$N$52*'Уравнения регрессии 1 ряд'!C41+'Уравнения регрессии 1 ряд'!$O$52*'Уравнения регрессии 1 ряд'!D41)+'Уравнения регрессии 2 ряд'!$O$124*('Уравнения регрессии 1 ряд'!$M$106+'Уравнения регрессии 1 ряд'!$N$106*'Уравнения регрессии 1 ряд'!C95+'Уравнения регрессии 1 ряд'!$O$106*'Уравнения регрессии 1 ряд'!D95) -> 1.2413238 | D3: ='Исходные данные'!B2 -> 0.904 | E3: y
A4: 2 | C4: ='Уравнения регрессии 2 ряд'!$M$124+'Уравнения регрессии 2 ряд'!$N$124*('Уравнения регрессии 1 ряд'!$M$52+'Уравнения регрессии 1 ряд'!$N$52*'Уравнения регрессии 1 ряд'!C42+'Уравнения регрессии 1 ряд'!$O$52*'Уравнения регрессии 1 ряд'!D42)+'Уравнения регрессии 2 ряд'!$O$124*('Уравнения регрессии 1 ряд'!$M$106+'Уравнения регрессии 1 ряд'!$N$106*'Уравнения регрессии 1 ряд'!C96+'Уравнения регрессии 1 ряд'!$O$106*'Уравнения регрессии 1 ряд'!D96) -> 1.2944691 | D4: ='Исходные данные'!B3 -> 0.922
A5: 3 | C5: ='Уравнения регрессии 2 ряд'!$M$124+'Уравнения регрессии 2 ряд'!$N$124*('Уравнения регрессии 1 ряд'!$M$52+'Уравнения регрессии 1 ряд'!$N$52*'Уравнения регрессии 1 ряд'!C43+'Уравнения регрессии 1 ряд'!$O$52*'Уравнения регрессии 1 ряд'!D43)+'Уравнения регрессии 2 ряд'!$O$124*('Уравнения регрессии 1 ряд'!$M$106+'Уравнения регрессии 1 ряд'!$N$106*'Уравнения регрессии 1 ряд'!C97+'Уравнения регрессии 1 ряд'!$O$106*'Уравнения регрессии 1 ряд'!D97) -> 0.7314502 | D5: ='Исходные данные'!B4 -> 0.763
A6: 4 | C6: ='Уравнения регрессии 2 ряд'!$M$124+'Уравнения регрессии 2 ряд'!$N$124*('Уравнения регрессии 1 ряд'!$M$52+'Уравнения регрессии 1 ряд'!$N$52*'Уравнения регрессии 1 ряд'!C44+'Уравнения регрессии 1 ряд'!$O$52*'Уравнения регрессии 1 ряд'!D44)+'Уравнения регрессии 2 ряд'!$O$124*('Уравнения регрессии 1 ряд'!$M$106+'Уравнения регрессии 1 ряд'!$N$106*'Уравнения регрессии 1 ряд'!C98+'Уравнения регрессии 1 ряд'!$O$106*'Уравнения регрессии 1 ряд'!D98) -> 1.2430981 | D6: ='Исходные данные'!B5 -> 0.923
A7: 5 | C7: ='Уравнения регрессии 2 ряд'!$M$124+'Уравнения регрессии 2 ряд'!$N$124*('Уравнения регрессии 1 ряд'!$M$52+'Уравнения регрессии 1 ряд'!$N$52*'Уравнения регрессии 1 ряд'!C45+'Уравнения регрессии 1 ряд'!$O$52*'Уравнения регрессии 1 ряд'!D45)+'Уравнения регрессии 2 ряд'!$O$124*('Уравнения регрессии 1 ряд'!$M$106+'Уравнения регрессии 1 ряд'!$N$106*'Уравнения регрессии 1 ряд'!C99+'Уравнения регрессии 1 ряд'!$O$106*'Уравнения регрессии 1 ряд'!D99) -> 1.2140998 | D7: ='Исходные данные'!B6 -> 0.918
A8: 6 | C8: ='Уравнения регрессии 2 ряд'!$M$124+'Уравнения регрессии 2 ряд'!$N$124*('Уравнения регрессии 1 ряд'!$M$52+'Уравнения регрессии 1 ряд'!$N$52*'Уравнения регрессии 1 ряд'!C46+'Уравнения регрессии 1 ряд'!$O$52*'Уравнения регрессии 1 ряд'!D46)+'Уравнения регрессии 2 ряд'!$O$124*('Уравнения регрессии 1 ряд'!$M$106+'Уравнения регрессии 1 ряд'!$N$106*'Уравнения регрессии 1 ряд'!C100+'Уравнения регрессии 1 ряд'!$O$106*'Уравнения регрессии 1 ряд'!D100) -> 1.2506465 | D8: ='Исходные данные'!B7 -> 0.906
A9: 7 | C9: ='Уравнения регрессии 2 ряд'!$M$124+'Уравнения регрессии 2 ряд'!$N$124*('Уравнения регрессии 1 ряд'!$M$52+'Уравнения регрессии 1 ряд'!$N$52*'Уравнения регрессии 1 ряд'!C47+'Уравнения регрессии 1 ряд'!$O$52*'Уравнения регрессии 1 ряд'!D47)+'Уравнения регрессии 2 ряд'!$O$124*('Уравнения регрессии 1 ряд'!$M$106+'Уравнения регрессии 1 ряд'!$N$106*'Уравнения регрессии 1 ряд'!C101+'Уравнения регрессии 1 ряд'!$O$106*'Уравнения регрессии 1 ряд'!D101) -> 1.1677374 | D9: ='Исходные данные'!B8 -> 0.905
A10: 8 | C10: ='Уравнения регрессии 2 ряд'!$M$124+'Уравнения регрессии 2 ряд'!$N$124*('Уравнения регрессии 1 ряд'!$M$52+'Уравнения регрессии 1 ряд'!$N$52*'Уравнения регрессии 1 ряд'!C48+'Уравнения регрессии 1 ряд'!$O$52*'Уравнения регрессии 1 ряд'!D48)+'Уравнения регрессии 2 ряд'!$O$124*('Уравнения регрессии 1 ряд'!$M$106+'Уравнения регрессии 1 ряд'!$N$106*'Уравнения регрессии 1 ряд'!C102+'Уравнения регрессии 1 ряд'!$O$106*'Уравнения регрессии 1 ряд'!D102) -> 0.47931623 | D10: ='Исходные данные'!B9 -> 0.545
A11: 9 | C11: ='Уравнения регрессии 2 ряд'!$M$124+'Уравнения регрессии 2 ряд'!$N$124*('Уравнения регрессии 1 ряд'!$M$52+'Уравнения регрессии 1 ряд'!$N$52*'Уравнения регрессии 1 ряд'!C49+'Уравнения регрессии 1 ряд'!$O$52*'Уравнения регрессии 1 ряд'!D49)+'Уравнения регрессии 2 ряд'!$O$124*('Уравнения регрессии 1 ряд'!$M$106+'Уравнения регрессии 1 ряд'!$N$106*'Уравнения регрессии 1 ряд'!C103+'Уравнения регрессии 1 ряд'!$O$106*'Уравнения регрессии 1 ряд'!D103) -> 1.2849478 | D11: ='Исходные данные'!B10 -> 0.894
A12: 10 | C12: ='Уравнения регрессии 2 ряд'!$M$124+'Уравнения регрессии 2 ряд'!$N$124*('Уравнения регрессии 1 ряд'!$M$52+'Уравнения регрессии 1 ряд'!$N$52*'Уравнения регрессии 1 ряд'!C50+'Уравнения регрессии 1 ряд'!$O$52*'Уравнения регрессии 1 ряд'!D50)+'Уравнения регрессии 2 ряд'!$O$124*('Уравнения регрессии 1 ряд'!$M$106+'Уравнения регрессии 1 ряд'!$N$106*'Уравнения регрессии 1 ряд'!C104+'Уравнения регрессии 1 ряд'!$O$106*'Уравнения регрессии 1 ряд'!D104) -> 1.2965979 | D12: ='Исходные данные'!B11 -> 0.9
A13: 11 | C13: ='Уравнения регрессии 2 ряд'!$M$124+'Уравнения регрессии 2 ряд'!$N$124*('Уравнения регрессии 1 ряд'!$M$52+'Уравнения регрессии 1 ряд'!$N$52*'Уравнения регрессии 1 ряд'!C51+'Уравнения регрессии 1 ряд'!$O$52*'Уравнения регрессии 1 ряд'!D51)+'Уравнения регрессии 2 ряд'!$O$124*('Уравнения регрессии 1 ряд'!$M$106+'Уравнения регрессии 1 ряд'!$N$106*'Уравнения регрессии 1 ряд'!C105+'Уравнения регрессии 1 ряд'!$O$106*'Уравнения регрессии 1 ряд'!D105) -> 1.3608444 | D13: ='Исходные данные'!B12 -> 0.932
A14: 12 | C14: ='Уравнения регрессии 2 ряд'!$M$124+'Уравнения регрессии 2 ряд'!$N$124*('Уравнения регрессии 1 ряд'!$M$52+'Уравнения регрессии 1 ряд'!$N$52*'Уравнения регрессии 1 ряд'!C52+'Уравнения регрессии 1 ряд'!$O$52*'Уравнения регрессии 1 ряд'!D52)+'Уравнения регрессии 2 ряд'!$O$124*('Уравнения регрессии 1 ряд'!$M$106+'Уравнения регрессии 1 ряд'!$N$106*'Уравнения регрессии 1 ряд'!C106+'Уравнения регрессии 1 ряд'!$O$106*'Уравнения регрессии 1 ряд'!D106) -> 0.68524628 | D14: ='Исходные данные'!B13 -> 0.74
